{
 "cells": [
  {
   "cell_type": "code",
   "execution_count": null,
   "id": "a7dcd37a-cb98-49ad-b73f-03f852913ecc",
   "metadata": {},
   "outputs": [],
   "source": [
    "Q1. What is an Exeption in python? Write the difference between Exceptions and syntax errors?"
   ]
  },
  {
   "cell_type": "code",
   "execution_count": null,
   "id": "d83ee163-2281-4e75-a277-66902e288e8c",
   "metadata": {},
   "outputs": [],
   "source": [
    "An exception in Python is an error that occurs during the execution of a program. It may be due to various reasons\n",
    "such as invalid input, division by zero, out of memory, or trying to access an undefined variable.\n",
    "When an exception occurs, the normal flow of the program is disrupted, and the program terminates.\n",
    "\n",
    "The key difference between exceptions and syntax errors is that exceptions occur during the execution of\n",
    "a program, while syntax errors occur before the program is executed. Additionally, exceptions can be handled and \n",
    "resolved programmatically, while syntax errors must be fixed manually by the programmer"
   ]
  },
  {
   "cell_type": "code",
   "execution_count": null,
   "id": "12574822-a648-4713-a579-f4358e034972",
   "metadata": {},
   "outputs": [],
   "source": [
    "Q2. What happens when an exception is not handled? Explain with an example"
   ]
  },
  {
   "cell_type": "code",
   "execution_count": null,
   "id": "a4fba607-02ac-4d7f-8459-781ba9f0f608",
   "metadata": {},
   "outputs": [],
   "source": [
    "When an exception is not handled, the program terminates abruptly and generates a traceback, which is a detailed\n",
    "report of the error that occurred. The traceback provides information about the line of code where the error \n",
    "occurred, the type of error, and a description of the error."
   ]
  },
  {
   "cell_type": "code",
   "execution_count": 2,
   "id": "779d80f6-253f-49ba-aff5-4d0cf07202ca",
   "metadata": {},
   "outputs": [
    {
     "name": "stdout",
     "output_type": "stream",
     "text": [
      "2.0\n"
     ]
    },
    {
     "ename": "ZeroDivisionError",
     "evalue": "division by zero",
     "output_type": "error",
     "traceback": [
      "\u001b[0;31m---------------------------------------------------------------------------\u001b[0m",
      "\u001b[0;31mZeroDivisionError\u001b[0m                         Traceback (most recent call last)",
      "Cell \u001b[0;32mIn[2], line 6\u001b[0m\n\u001b[1;32m      3\u001b[0m     \u001b[38;5;28;01mreturn\u001b[39;00m result\n\u001b[1;32m      5\u001b[0m \u001b[38;5;28mprint\u001b[39m(divide(\u001b[38;5;241m10\u001b[39m, \u001b[38;5;241m5\u001b[39m))\n\u001b[0;32m----> 6\u001b[0m \u001b[38;5;28mprint\u001b[39m(\u001b[43mdivide\u001b[49m\u001b[43m(\u001b[49m\u001b[38;5;241;43m10\u001b[39;49m\u001b[43m,\u001b[49m\u001b[43m \u001b[49m\u001b[38;5;241;43m0\u001b[39;49m\u001b[43m)\u001b[49m)\n",
      "Cell \u001b[0;32mIn[2], line 2\u001b[0m, in \u001b[0;36mdivide\u001b[0;34m(x, y)\u001b[0m\n\u001b[1;32m      1\u001b[0m \u001b[38;5;28;01mdef\u001b[39;00m \u001b[38;5;21mdivide\u001b[39m(x, y):\n\u001b[0;32m----> 2\u001b[0m     result \u001b[38;5;241m=\u001b[39m \u001b[43mx\u001b[49m\u001b[43m \u001b[49m\u001b[38;5;241;43m/\u001b[39;49m\u001b[43m \u001b[49m\u001b[43my\u001b[49m\n\u001b[1;32m      3\u001b[0m     \u001b[38;5;28;01mreturn\u001b[39;00m result\n",
      "\u001b[0;31mZeroDivisionError\u001b[0m: division by zero"
     ]
    }
   ],
   "source": [
    "def divide(x, y):\n",
    "    result = x / y\n",
    "    return result\n",
    "\n",
    "print(divide(10, 5))\n",
    "print(divide(10, 0))"
   ]
  },
  {
   "cell_type": "code",
   "execution_count": null,
   "id": "da01095d-bc86-4aa6-8016-2033d357789c",
   "metadata": {},
   "outputs": [],
   "source": [
    "Q3. Which Python statements are used to catch and handle exceptions? Explain with an example"
   ]
  },
  {
   "cell_type": "code",
   "execution_count": null,
   "id": "d2800ece-e90b-4f2f-844f-d97e6698419b",
   "metadata": {},
   "outputs": [],
   "source": [
    "In Python, exceptions can be caught and handled using the try and except statements. The try block contains \n",
    "the code that might raise an exception, and the except block contains the code that will handle the exception \n",
    "if it occurs.\n",
    "Here is an example of how to use the try and except statements to handle a ZeroDivisionError exception:"
   ]
  },
  {
   "cell_type": "code",
   "execution_count": 3,
   "id": "aa9db911-f7de-4e92-96f1-501361768cab",
   "metadata": {},
   "outputs": [
    {
     "name": "stdout",
     "output_type": "stream",
     "text": [
      "2.0\n",
      "Cannot divide by zero\n",
      "None\n"
     ]
    }
   ],
   "source": [
    "def divide(x, y):\n",
    "    try:\n",
    "        result = x / y\n",
    "    except ZeroDivisionError:\n",
    "        print(\"Cannot divide by zero\")\n",
    "    else:\n",
    "        return result\n",
    "\n",
    "print(divide(10, 5)) # Output: 2.0\n",
    "print(divide(10, 0)) # Output: Cannot divide by zero"
   ]
  },
  {
   "cell_type": "code",
   "execution_count": null,
   "id": "9eedff1e-470c-4963-8999-667adee5a479",
   "metadata": {},
   "outputs": [],
   "source": [
    "Q4. Explain with an example:#\n",
    "\n",
    "try and else\n",
    "finally\n",
    "raise"
   ]
  },
  {
   "cell_type": "code",
   "execution_count": 4,
   "id": "c6fcf66b-0d5d-43a6-bcd6-4baae403c044",
   "metadata": {},
   "outputs": [
    {
     "name": "stdout",
     "output_type": "stream",
     "text": [
      "2.0\n",
      "5.0\n"
     ]
    }
   ],
   "source": [
    "# try and else statements can be used in combination to handle exceptions in Python. The else block is executed if no exceptions are raised in the try block.\n",
    "#example\n",
    "\n",
    "def divide(x, y):\n",
    "    try:\n",
    "        result = x / y\n",
    "    except ZeroDivisionError:\n",
    "        print(\"Cannot divide by zero\")\n",
    "    else:\n",
    "        return result\n",
    "\n",
    "print(divide(10, 5)) # Output: 2.0\n",
    "print(divide(10, 2)) # Output: 5.0\n"
   ]
  },
  {
   "cell_type": "code",
   "execution_count": 5,
   "id": "e3318244-c063-4010-bdf9-d59c60bba2c9",
   "metadata": {},
   "outputs": [
    {
     "name": "stdout",
     "output_type": "stream",
     "text": [
      "Executing finally block\n",
      "2.0\n",
      "Cannot divide by zero\n",
      "Executing finally block\n",
      "None\n"
     ]
    }
   ],
   "source": [
    "#The finally statement in Python is used to specify a block of code that should be executed regardless of whether an exception occurs or not. The code in the finally block is guaranteed to be executed, even if an exception is raised and not caught in the try block.\n",
    "#example\n",
    "def divide(x, y):\n",
    "    try:\n",
    "        result = x / y\n",
    "    except ZeroDivisionError:\n",
    "        print(\"Cannot divide by zero\")\n",
    "        result = None\n",
    "    finally:\n",
    "        print(\"Executing finally block\")\n",
    "    return result\n",
    "\n",
    "print(divide(10, 5)) # Output: Executing finally block \\n 2.0\n",
    "print(divide(10, 0)) # Output: Cannot divide by zero \\n Executing finally block \\n None"
   ]
  },
  {
   "cell_type": "code",
   "execution_count": 6,
   "id": "e456115f-dcbc-4aa1-ac02-f16967d03b79",
   "metadata": {},
   "outputs": [
    {
     "name": "stdout",
     "output_type": "stream",
     "text": [
      "2.0\n",
      "Cannot divide by zero\n"
     ]
    }
   ],
   "source": [
    "#The raise statement in Python is used to raise an exception explicitly. It is used to indicate that an error has occurred and to stop the normal execution of the program.\n",
    "#example\n",
    "\n",
    "def divide(x, y):\n",
    "    if y == 0:\n",
    "        raise ZeroDivisionError(\"Cannot divide by zero\")\n",
    "    return x / y\n",
    "\n",
    "try:\n",
    "    print(divide(10, 5)) # Output: 2.0\n",
    "    print(divide(10, 0))\n",
    "except ZeroDivisionError as e:\n",
    "    print(e) # Output: Cannot divide by zero"
   ]
  },
  {
   "cell_type": "code",
   "execution_count": null,
   "id": "a6d2fe97-c4d0-4595-9e02-65dba64f2c72",
   "metadata": {},
   "outputs": [],
   "source": [
    "Q5. What are Custom Exceptions in python? What do we need Custom Exceptions ? Explain in with an example"
   ]
  },
  {
   "cell_type": "code",
   "execution_count": null,
   "id": "8d2d6dc5-8c64-4861-8cc5-15a6efc0cf76",
   "metadata": {},
   "outputs": [],
   "source": [
    "Custom exceptions are user-defined exceptions in Python. They allow you to define specific types of exceptions\n",
    "for your application, so you can handle errors and exceptions in a more organized and meaningful way.\n",
    "\n",
    "For example, consider a scenario where you are writing a library that performs some mathematical calculations.\n",
    "In this library, you may encounter several different types of errors, such as invalid input, overflow, and \n",
    "divide-by-zero errors. You could handle these errors by raising built-in exceptions, such as ValueError or\n",
    "ZeroDivisionError, but it may not provide enough context or information about the error that has occurred."
   ]
  },
  {
   "cell_type": "code",
   "execution_count": 7,
   "id": "d9036f9e-7be0-44e2-a032-a18d1ccf4dfd",
   "metadata": {},
   "outputs": [
    {
     "name": "stdout",
     "output_type": "stream",
     "text": [
      "2.0\n",
      "Input values must be positive\n",
      "None\n",
      "Cannot divide by zero\n",
      "None\n"
     ]
    }
   ],
   "source": [
    "class InvalidInputError(Exception):\n",
    "    pass\n",
    "\n",
    "class OverflowError(Exception):\n",
    "    pass\n",
    "\n",
    "class DivideByZeroError(Exception):\n",
    "    pass\n",
    "\n",
    "def divide(x, y):\n",
    "    if y == 0:\n",
    "        raise DivideByZeroError(\"Cannot divide by zero\")\n",
    "    return x / y\n",
    "\n",
    "def calculate(x, y):\n",
    "    try:\n",
    "        if x < 0 or y < 0:\n",
    "            raise InvalidInputError(\"Input values must be positive\")\n",
    "        result = divide(x, y)\n",
    "    except DivideByZeroError as e:\n",
    "        print(e)\n",
    "    except InvalidInputError as e:\n",
    "        print(e)\n",
    "    else:\n",
    "        return result\n",
    "\n",
    "print(calculate(10, 5)) # Output: 2.0\n",
    "print(calculate(-10, 5)) # Output: Input values must be positive\n",
    "print(calculate(10, 0)) # Output: Cannot divide by zero"
   ]
  },
  {
   "cell_type": "code",
   "execution_count": null,
   "id": "6d048036-7db0-4689-b2c7-5c64a0123c12",
   "metadata": {},
   "outputs": [],
   "source": [
    "Q6. Create a custom exception class. Use this class to handle an exception."
   ]
  },
  {
   "cell_type": "code",
   "execution_count": 8,
   "id": "6035e7e1-589c-4306-95d0-204644d8f587",
   "metadata": {},
   "outputs": [
    {
     "name": "stdout",
     "output_type": "stream",
     "text": [
      "2.0\n",
      "Cannot divide by zero\n"
     ]
    }
   ],
   "source": [
    "class CustomException(Exception):\n",
    "    pass\n",
    "\n",
    "def divide(x, y):\n",
    "    if y == 0:\n",
    "        raise CustomException(\"Cannot divide by zero\")\n",
    "    return x / y\n",
    "\n",
    "try:\n",
    "    print(divide(10, 5)) # Output: 2.0\n",
    "    print(divide(10, 0))\n",
    "except CustomException as e:\n",
    "    print(e) # Output: Cannot divide by zero"
   ]
  },
  {
   "cell_type": "code",
   "execution_count": null,
   "id": "16c4bba6-b1ab-4afe-96f0-811c6b0d7aad",
   "metadata": {},
   "outputs": [],
   "source": []
  }
 ],
 "metadata": {
  "kernelspec": {
   "display_name": "Python 3 (ipykernel)",
   "language": "python",
   "name": "python3"
  },
  "language_info": {
   "codemirror_mode": {
    "name": "ipython",
    "version": 3
   },
   "file_extension": ".py",
   "mimetype": "text/x-python",
   "name": "python",
   "nbconvert_exporter": "python",
   "pygments_lexer": "ipython3",
   "version": "3.10.8"
  }
 },
 "nbformat": 4,
 "nbformat_minor": 5
}
